<?xml version="1.0"?>

<robot name="prrp" xmlns:xacro="http://www.ros.org/wiki/xacro">

    <!-- Import all Gazebo-customization elements, including Gazebo colors -->
    <xacro:include filename="$(find rsd_description)/urdf/prrp.gazebo" />

    <!-- Transmission Macros -->

    <xacro:macro name="gazebo_trans" params="prefix">
        <transmission name="joint_${prefix}_trans">
            <type>transmission_interface/SimpleTransmission</type>
            <joint name="joint_${prefix}">
                <hardwareInterface>hardware_interface/EffortJointInterface</hardwareInterface>
            </joint>
            <actuator name="actuator_${prefix}">
                <hardwareInterface>hardware_interface/EffortJointInterface</hardwareInterface>
                <mechanicalReduction>1</mechanicalReduction>
            </actuator>
        </transmission>
    </xacro:macro>
    <!-- Usage : <xacro:gazebo_trans prefix="1"/> -->

    <!-- Gazebo Link Property Macros -->
    <xacro:macro name="gazebo_links" params="prefix">
        <gazebo reference="${prefix}">
            <selfCollide>false</selfCollide>
            <mu1 value="0.8"/>
            <mu2 value="0.8"/>
            <!-- <kp value="10000000.0" />
            <kd value="1" />
            <fdir1 value="1 0 0"/> -->
        </gazebo>
    </xacro:macro>
    <!-- Usage : <xacro:gazebo_links prefix="head"/> -->

    <link name="base_link">
        <visual>
            <geometry>
                <box size="0.4 0.6 0.02"/>
            </geometry>
            <origin rpy="0 0 0" xyz="0 0.2 0"/>
            <material name="grey2">
                <color rgba="0.9 0.9 0.9 1"/>
            </material>
        </visual>

        <collision>
            <geometry>
                <box size="0.4 0.6 0.02"/>
            </geometry>
            <origin rpy="0 0 0" xyz="0 0.2 0"/>
        </collision>

        <inertial>
            <mass value="100000"/>
            <inertia ixx="3333.33333333" ixy="0.0" ixz="0.0" iyy="1666.66666667" iyz="0.0" izz="1666.66666667"/>
        </inertial>
    </link>

    <link name="pan_link">
        <visual>
            <geometry>
                <cylinder length="0.2" radius="0.02"/>
            </geometry>
            <origin rpy="0 0 0" xyz="0 0 0.09"/>
            <material name="black">
                <color rgba="0 0 0 1"/>
            </material>
        </visual>

        <collision>
            <geometry>
                <cylinder length="0.2" radius="0.03"/>
            </geometry>
            <origin rpy="0 0 0" xyz="0 0 0.09"/>
        </collision>

        <inertial>
            <mass value="0.1"/>
            <inertia ixx="0.000343333333333" ixy="0.0" ixz="0.0" iyy="0.000343333333333" iyz="0.0" izz="2e-05"/>
        </inertial>
    </link>

    <link name="link_1">
        <visual>
            <geometry>
                <cylinder length="0.1" radius="0.025"/>
            </geometry>
            <origin rpy="0 0 0" xyz="0 0 0"/>
            <material name="grey">
                <color rgba="0.25 0.25 0.25 1"/>
            </material>
        </visual>

        <collision>
            <geometry>
                <cylinder length="0.1" radius="0.03"/>
            </geometry>
            <origin rpy="0 0 0" xyz="0 0 0"/>
        </collision>

        <inertial>
            <mass value="0.1"/>
            <inertia ixx="9.89583333333e-05" ixy="0.0" ixz="0.0" iyy="9.89583333333e-05" iyz="0.0" izz="3.125e-05"/>
        </inertial>
    </link>

    <link name="link_2">
        <visual>
            <geometry>
                <box size="0.1 0.2 0.02"/>
            </geometry>
            <origin rpy="0 0 0" xyz="0 0.1 0"/>
            <material name="black">
                <color rgba="0 0 0 1"/>
            </material>
        </visual>

        <collision>
            <geometry>
                <box size="0.1 0.2 0.02"/>
            </geometry>
            <origin rpy="0 0 0" xyz="0 0.1 0"/>
        </collision>

        <inertial>
            <mass value="0.1"/>
            <inertia ixx="0.000336666666667" ixy="0.0" ixz="0.0" iyy="8.66666666667e-05" iyz="0.0" izz="0.000416666666667"/>
        </inertial>
    </link>
    
    <link name="link_3">
        <visual>
            <geometry>
                <box size="0.1 0.2 0.02"/>
            </geometry>
            <origin rpy="0 0 0" xyz="0 0.1 0"/>
            <material name="grey">
                <color rgba="0.25 0.25 0.25 1"/>
            </material>
        </visual>

        <collision>
            <geometry>
                <box size="0.1 0.2 0.02"/>
            </geometry>
            <origin rpy="0 0 0" xyz="0 0.1 0"/>
        </collision>

        <inertial>
            <mass value="0.1"/>
            <inertia ixx="0.000336666666667" ixy="0.0" ixz="0.0" iyy="8.66666666667e-05" iyz="0.0" izz="0.000416666666667"/>
        </inertial>
    </link>
    
    <link name="link_4">
        <visual>
            <geometry>
                <cylinder length="0.12" radius="0.025"/>
            </geometry>
            <origin rpy="0 0 0" xyz="0 0 -0.05"/>
            <material name="grey">
                <color rgba="0.25 0.25 0.25 1"/>
            </material>
        </visual>

        <collision>
            <geometry>
                <cylinder length="0.1" radius="0.03"/>
            </geometry>
            <origin rpy="0 0 0" xyz="0 0 0"/>
        </collision>

        <inertial>
            <mass value="0.1"/>
            <inertia ixx="0.000135625" ixy="0.0" ixz="0.0" iyy="0.000135625" iyz="0.0" izz="3.125e-05"/>
        </inertial>
    </link>

    <link name="link_5">
        <visual>
            <geometry>
                <cylinder length="0.1" radius="0.02"/>
            </geometry>
            <origin rpy="0 0 0" xyz="0 0 -0.05"/>
            <material name="black">
                <color rgba="0 0 0 1"/>
            </material>
        </visual>

        <collision>
            <geometry>
                <cylinder length="0.1" radius="0.025"/>
            </geometry>
            <origin rpy="0 0 0" xyz="0 0 0"/>
        </collision>

        <inertial>
            <mass value="0.1"/>
            <inertia ixx="9.33333333333e-05" ixy="0.0" ixz="0.0" iyy="9.33333333333e-05" iyz="0.0" izz="2e-05"/>
        </inertial>
    </link>


    <joint name="joint_1" type="prismatic">
        <parent link="pan_link"/>
        <child link="link_1"/>
        <origin xyz="0 0 0.2"/>
        <axis xyz="0 0 1" />
        <limit effort="300" velocity="0.1" lower="-0.1" upper="0.1"/>
        <dynamics damping="50" friction="1"/>
    </joint>

    <joint name="joint_2" type="revolute">
        <parent link="link_1"/>
        <child link="link_2"/>
        <origin xyz="0 0 0.05"/>
        <axis xyz="0 0 1" />
        <limit effort="300" velocity="0.1" lower="-3.14" upper="3.14"/>
        <dynamics damping="50" friction="1"/>
    </joint>   

    <joint name="joint_3" type="revolute">
        <parent link="link_2"/>
        <child link="link_3"/>
        <origin xyz="0 0.2 -0.02"/>
        <axis xyz="0 0 1" />
        <limit effort="300" velocity="0.1" lower="-3.14" upper="3.14"/>
        <dynamics damping="50" friction="1"/>
    </joint>

    <joint name="fixed" type="fixed">
        <parent link="link_3"/>
        <child link="link_4"/>
        <origin xyz="0 0.2 0"/>
        <axis xyz="0 0 1" />
        <limit effort="300" velocity="0.1" lower="-0.1" upper="0.1"/>
        <dynamics damping="50" friction="1"/>
    </joint>

    <joint name="joint_4" type="prismatic">
        <parent link="link_4"/>
        <child link="link_5"/>
        <origin xyz="0 0 0"/>
        <axis xyz="0 0 1" />
        <limit effort="300" velocity="0.1" lower="-0.1" upper="-0.01"/>
        <dynamics damping="50" friction="1"/>
    </joint>

    <!-- Transmissions -->
    <xacro:gazebo_trans prefix="1"/>
    <xacro:gazebo_trans prefix="2"/>
    <xacro:gazebo_trans prefix="3"/>
    <xacro:gazebo_trans prefix="4"/>


    <!-- Link Propertys -->
    <xacro:gazebo_links prefix="base_link"/>
    <xacro:gazebo_links prefix="pan_link"/>
    <xacro:gazebo_links prefix="link_1"/>
    <xacro:gazebo_links prefix="link_2"/>
    <xacro:gazebo_links prefix="link_3"/>
    <xacro:gazebo_links prefix="link_4"/>
    <xacro:gazebo_links prefix="link_5"/>

</robot>